<sdf version="1.10">
  <model name="auv">
  
    <!--________________plugins_________________-->  
    <plugin filename="gz-sim-odometry-publisher-system" name="gz::sim::systems::OdometryPublisher">
        <odom_frame>chassis_link</odom_frame>
        <odom_publish_frequency>400</odom_publish_frequency> 
        <dimensions>3</dimensions>
        <rpy_offset>0 0 0</rpy_offset>
    </plugin>

    <plugin filename="gz-sim-buoyancy-engine-system" name="gz::sim::systems::BuoyancyEngine">
      <link_name>chassis_link</link_name>
      <namespace>ags</namespace>
      <min_volume>0.04000</min_volume>
      <neutral_volume>0.05267</neutral_volume>
      <default_volume>0.05267</default_volume>
      <max_volume>0.0600</max_volume>
      <max_inflation_rate>0.00001</max_inflation_rate>
      <fluid_density>1030</fluid_density>
      <surface>0</surface>
    </plugin>

    <plugin filename="gz-sim-hydrodynamics-system" name="gz::sim::systems::Hydrodynamics">
      <link_name>chassis_link</link_name>
      <water_density>1000.0</water_density>
      
        <xDotU>7.830329E-01</xDotU>  
        <yDotV>-5.062522E+01</yDotV>  
        <zDotW>-5.062522E+01</zDotW>  
        <kDotP>-3.913712E-01</kDotP>  
        <mDotQ>-6.885066E+00</mDotQ>  
        <nDotR>-6.885066E+00</nDotR>  
        
        <xU>0.0</xU>
        <yV>0.0</yV>
        <zW>0.0</zW>
        <kP>0.0</kP>
        <mQ>0.0</mQ>
        <nR>0.0</nR>
        
        <xUabsU>-1.479637E+00</xUabsU> 
        <yVabsV>-1.258586E+02</yVabsV> 
        <zWabsW>-1.258586E+02</zWabsW> 
        <kPabsP>0.000000E+00</kPabsP>  
        <mQabsQ>-6.347858E+00</mQabsQ> 
        <nRabsR>-6.347858E+00</nRabsR> 
    </plugin>

    <!-- _______________________chassis link_______________________-->    
    <link name="chassis_link">
      <inertial>
        <pose>0.096007 0.10167 0.10982 0 0 0</pose>
        <mass>0.0362</mass>
        <!-- <mass>6.0362</mass> -->
        <inertia>
          <ixx>0.04236</ixx>
          <ixy>-2.5021E-09</ixy>
          <ixz>-1.3686E-05</ixz>
          <iyy>0.18568</iyy>
          <iyz>1.879E-05</iyz>
          <izz>0.14514</izz>
        </inertia>
      </inertial>

      <visual name="chassis_visual">
        <pose>0 0 0 0 0 0</pose>
        <geometry>
          <mesh>
            <scale>1 1 1</scale>
            <uri>model://meshes/chassis_link.STL</uri>
          </mesh>
        </geometry>
        <material>
          <diffuse>0.941174984 0.941174984 0.941174984 1</diffuse>
          <ambient>0.941174984 0.941174984 0.941174984 1</ambient>
          <specular>0.1 0.1 0.1 1</specular>
          <emissive>0 0 0 0</emissive>
        </material>
      </visual>

      <collision name="chassis_collision">
        <pose>0 0 0 0 0 0</pose>
        <geometry>
          <mesh>
            <scale>1 1 1</scale>
            <uri>model://meshes/chassis_link.STL</uri>
          </mesh>
        </geometry>
      </collision>
    </link>

      <!--_____________________hull link_______________________-->
      <link name="hull_link">

        <inertial>
          <pose>0.0075921 0.089964 1.0578E-05 0 0 0</pose>
          <mass>22</mass>
          <!-- <mass>15</mass> -->
          <inertia>
            <ixx>0.03422</ixx>
            <ixy>-0.0010072</ixy>
            <ixz>2.3337E-05</ixz>
            <iyy>0.085969</iyy>
            <iyz>-2.3338E-05</iyz>
            <izz>0.077582</izz>
          </inertia>
        </inertial>
 
        <visual name="hull_visual">
          <pose>0 0 0 0 0 0</pose>
          <geometry>
            <mesh>
              <uri>model://meshes/hull_link.STL</uri>
            </mesh>
          </geometry>
          <material>
            <ambient>1 0 1 1</ambient>     <!-- RGBA: Magenta -->
            <diffuse>1 0 1 1</diffuse>     <!-- Used for surface lighting -->
            <specular>0.1 0.1 0.1 1</specular> <!-- Highlight color -->
            <emissive>0 0 0 1</emissive> 
            
          </material>
        </visual>

        <collision name="hull_collision">
          <pose>0 0 0 0 0 0</pose>
          <geometry>
            <mesh>
              <uri>model://meshes/hull_link.STL</uri>
            </mesh>
          </geometry>
        </collision>

      <pose>0.095605167680179 -0.114810636913522 0.0727763991682185 1.5707963267949 0.0 0.0</pose></link>

      <joint name="hull_joint" type="fixed">
          <pose>0.095605167680179 -0.114810636913522 0.0727763991682185 1.5707963267949 0 0</pose>
          <parent>chassis_link</parent>
          <child>hull_link</child>
          
      </joint>

      <!--_______________________thruster 1_______________________-->
      <link name="t1_link">
        <inertial>
          <pose>-4.1153E-07 -0.00055898 -0.0039322 0 0 0</pose>
          <mass>0.226</mass>
          <inertia>
            <ixx>0.00013148</ixx>
            <ixy>-1.6857E-09</ixy>
            <ixz>-1.9632E-09</ixz>
            <iyy>0.00012745</iyy>
            <iyz>-1.4772E-07</iyz>
            <izz>0.00018193</izz>
          </inertia>
        </inertial>

        <visual name="t1v">
          <pose>0 0 0 0 0 0</pose>
          <geometry>
            <mesh>
              <scale>1 1 1</scale>
              <uri>model://meshes/t1_link.STL</uri>
            </mesh>
          </geometry>
          <material>
            <script>
              <uri>file://media/materials/scripts/gazebo.material</uri>
                <name>Gazebo/Blue</name>
            </script>
          </material>
        </visual>

        <collision name="t1c">
          <pose>0 0 0 0 0 0</pose>
          <geometry>
            <mesh>
              <uri>model://meshes/t1_link.STL</uri>
            </mesh>
          </geometry>
        </collision>

      <pose>0.349878584893384 0.0539678164692632 0.187776399168219 1.5707963267949 0.0 0.785531324064394</pose></link>

      <joint name="t1_joint" type="revolute">
        <pose>0.349878584893384 0.0539678164692632 0.187776399168219 1.5707963267949 0 0.785531324064394</pose>
        <parent>chassis_link</parent>
          <child>t1_link</child>
          <axis>
            <xyz>1 0 0</xyz>
          </axis>
      </joint>

      <plugin filename="gz-sim-thruster-system" name="gz::sim::systems::Thruster">
        <namespace>ags</namespace>
        <joint_name>t1_joint</joint_name>
        <thrust_coefficient>0.02</thrust_coefficient>
        <fluid_density>1000.0</fluid_density>
        <propeller_diameter>0.1</propeller_diameter>
        <velocity_control>true</velocity_control>
        <use_angvel_cmd>false</use_angvel_cmd>
      </plugin> 

    

    
      <!--_______________________thruster 2_______________________-->
      <link name="t2_link">
        <inertial>
          <pose>-4.1153E-07 -0.00055898 -0.0039322 0 0 0</pose>
          <mass>0.226</mass>
          <inertia>
            <ixx>0.00013148</ixx>
            <ixy>-1.6857E-09</ixy>
            <ixz>-1.9632E-09</ixz>
            <iyy>0.00012745</iyy>
            <iyz>-1.4772E-07</iyz>
            <izz>0.00018193</izz>
          </inertia>
        </inertial>

        <visual name="t2v">
          <pose>0 0 0 0 0 0</pose>
          <geometry>
            <mesh>
              <scale>1 1 1</scale>
              <uri>model://meshes/t2_link.STL</uri>
            </mesh>
          </geometry>
          <material>
            <script>
              <uri>file://media/materials/scripts/gazebo.material</uri>
                <name>Gazebo/Blue</name>
            </script>
          </material>
        </visual>

        <collision name="t2c">
          <pose>0 0 0 0 0 0</pose>
          <geometry>
            <mesh>
              <uri>model://meshes/t2_link.STL</uri>
            </mesh>
          </geometry>
        </collision>

      <pose>0.349878584893391 -0.283589090296312 0.187776399168219 1.5707963267949 0.0 2.3560613295254</pose></link>

      <joint name="t2_joint" type="revolute">
          <pose>0.34987858489339102 -0.28358909029631202 0.187776399168219 1.5707963267949001 5.5511151231257827e-17 2.3560613295253998</pose>
          <parent>chassis_link</parent>
          <child>t2_link</child>
          <axis>
            <xyz>1 0 0</xyz>
          </axis>
      </joint>

      <plugin filename="gz-sim-thruster-system" name="gz::sim::systems::Thruster">
        <namespace>ags</namespace>
        <joint_name>t2_joint</joint_name>
        <thrust_coefficient>0.02</thrust_coefficient>
        <fluid_density>1000.0</fluid_density>
        <propeller_diameter>0.1</propeller_diameter>
        <velocity_control>true</velocity_control>
        <use_angvel_cmd>false</use_angvel_cmd>
      </plugin>

   

    
      <!--_______________________thruster 3_______________________-->
      <link name="t3_link">
        <inertial>
          <pose>-4.1153E-07 -0.00055898 -0.0039322 0 0 0</pose>
          <mass>0.226</mass>
          <inertia>
            <ixx>0.00013148</ixx>
            <ixy>-1.6857E-09</ixy>
            <ixz>-1.9632E-09</ixz>
            <iyy>0.00012745</iyy>
            <iyz>-1.4772E-07</iyz>
            <izz>0.00018193</izz>
          </inertia>
        </inertial>

        <visual name="t3v">
          <pose>0 0 0 0 0 0</pose>
          <geometry>
            <mesh>
              <scale>1 1 1</scale>
              <uri>model://meshes/t3_link.STL</uri>
            </mesh>
          </geometry>
          <material>
            <script>
              <uri>file://media/materials/scripts/gazebo.material</uri>
                <name>Gazebo/Blue</name>
            </script>
          </material>
        </visual>

        <collision name="t3c">
          <pose>0 0 0 0 0 0</pose>
          <geometry>
            <mesh>
              <uri>model://meshes/t3_link.STL</uri>
            </mesh>
          </geometry>
        </collision>

      <pose>-0.154694276907376 -0.283521901037111 0.187776399168219 1.5707963267949 0.0 -2.35632765085928</pose></link>
      
      <joint name="t3_joint" type="revolute">
          <pose>-0.154694276907376 -0.283521901037111 0.187776399168219 1.5707963267949003 -5.5511151231257827e-17 -2.3563276508592801</pose>
          <parent>chassis_link</parent>
          <child>t3_link</child>
          <axis>
            <xyz>1 0 0</xyz>
          </axis>
      </joint>

      <plugin filename="gz-sim-thruster-system" name="gz::sim::systems::Thruster">
        <namespace>ags</namespace>
        <joint_name>t3_joint</joint_name>
        <thrust_coefficient>0.02</thrust_coefficient>
        <fluid_density>1000.0</fluid_density>
        <propeller_diameter>0.1</propeller_diameter>
        <velocity_control>true</velocity_control>
        <use_angvel_cmd>false</use_angvel_cmd>
      </plugin>

    

    
      <!--_______________________thruster 4_______________________-->
      <link name="t4_link">
        <inertial>
          <pose>-4.1153E-07 -0.00055898 -0.0039322 0 0 0</pose>
          <mass>0.226</mass>
          <inertia>
            <ixx>0.00013148</ixx>
            <ixy>-1.6857E-09</ixy>
            <ixz>-1.9632E-09</ixz>
            <iyy>0.00012745</iyy>
            <iyz>-1.4772E-07</iyz>
            <izz>0.00018193</izz>
          </inertia>
        </inertial>

        <visual name="t4v">
          <pose>0 0 0 0 0 0</pose>
          <geometry>
            <mesh>
              <scale>1 1 1</scale>
              <uri>model://meshes/t4_link.STL</uri>
            </mesh>
          </geometry>
          <material>
            <script>
              <uri>file://media/materials/scripts/gazebo.material</uri>
                <name>Gazebo/Blue</name>
            </script>
          </material>
        </visual>

        <collision name="t4c">
          <pose>0 0 0 0 0 0</pose>
          <geometry>
            <mesh>
              <uri>model://meshes/t4_link.STL</uri>
            </mesh>
          </geometry>
        </collision>

      <pose>-0.154604378302771 0.0540349937575058 0.187776399168219 1.5707963267949 0.0 -0.785797645398278</pose></link>
      
      <joint name="t4_joint" type="revolute">
          <pose>-0.15460437830277099 0.054034993757505798 0.187776399168219 1.5707963267949003 1.1102230246251565e-16 -0.78579764539827812</pose>
          <parent>chassis_link</parent>
          <child>t4_link</child>
          <axis>
            <xyz>1 0 0</xyz>
          </axis>
      </joint>

      <plugin filename="gz-sim-thruster-system" name="gz::sim::systems::Thruster">
        <namespace>ags</namespace>
        <joint_name>t4_joint</joint_name>
        <thrust_coefficient>0.02</thrust_coefficient>
        <fluid_density>1000.0</fluid_density>
        <propeller_diameter>0.1</propeller_diameter>
        <velocity_control>true</velocity_control>
        <use_angvel_cmd>false</use_angvel_cmd>
      </plugin>

   

    
      <!--_______________________thruster 5_______________________-->
      <link name="t5_link">
        <inertial>
          <pose>-4.1153E-07 -0.00055898 -0.0039322 0 0 0</pose>
          <mass>0.226</mass>
          <inertia>
            <ixx>0.00013148</ixx>
            <ixy>-1.6857E-09</ixy>
            <ixz>-1.9632E-09</ixz>
            <iyy>0.00012745</iyy>
            <iyz>-1.4772E-07</iyz>
            <izz>0.00018193</izz>
          </inertia>
        </inertial>

        <visual name="t5v">
          <pose>0 0 0 0 0 0</pose>
          <geometry>
            <mesh>
              <scale>1 1 1</scale>
              <uri>model://meshes/t5_link.STL</uri>
            </mesh>
          </geometry>
          <material>
            <script>
              <uri>file://media/materials/scripts/gazebo.material</uri>
                <name>Gazebo/Blue</name>
            </script>
          </material>
        </visual>

        <collision name="t5c">
          <pose>0 0 0 0 0 0</pose>
          <geometry>
            <mesh>
              <uri>model://meshes/t5_link.STL</uri>
            </mesh>
          </geometry>
        </collision>

      <pose>0.23263659031711 0.05014009154751 0.097524622545968 0.0 0.0 3.14145949292285</pose>
      </link>
      
      <joint name="t5_joint" type="revolute">
          <pose>0.23263659031711001 0.05014009154751 0.097524622545967998 0 0 3.1414594929228499</pose>
          <parent>chassis_link</parent>
          <child>t5_link</child>
          <axis>
            <xyz>1 0 0</xyz>
          </axis>
      </joint>

      <plugin filename="gz-sim-thruster-system" name="gz::sim::systems::Thruster">
        <namespace>ags</namespace>
        <joint_name>t5_joint</joint_name>
        <thrust_coefficient>0.02</thrust_coefficient>
        <fluid_density>1000.0</fluid_density>
        <propeller_diameter>0.1</propeller_diameter>
        <velocity_control>true</velocity_control>
        <use_angvel_cmd>false</use_angvel_cmd>
      </plugin>
  

    
      <!--_______________________thruster 6_______________________-->
      <link name="t6_link">
        <inertial>
          <pose>-4.1153E-07 -0.00055898 -0.0039322 0 0 0</pose>
          <mass>0.226</mass>
          <inertia>
            <ixx>0.00013148</ixx>
            <ixy>-1.6857E-09</ixy>
            <ixz>-1.9632E-09</ixz>
            <iyy>0.00012745</iyy>
            <iyz>-1.4772E-07</iyz>
            <izz>0.00018193</izz>
          </inertia>
        </inertial>

        <visual name="t6v">
          <pose>0 0 0 0 0 0</pose>
          <geometry>
            <mesh>
              <scale>1 1 1</scale>
              <uri>model://meshes/t6_link.STL</uri>
            </mesh>
          </geometry>
          <material>
            <script>
              <uri>file://media/materials/scripts/gazebo.material</uri>
                <name>Gazebo/Blue</name>
            </script>
          </material>
        </visual>

        <collision name="t6c">
          <pose>0 0 0 0 0 0</pose>
          <geometry>
            <mesh>
              <uri>model://meshes/t6_link.STL</uri>
            </mesh>
          </geometry>
        </collision>

      <pose>0.23259264729715 -0.279859905526749 0.0975246225459646 0.0 0.0 -0.000133160666942421</pose></link>
      
      <joint name="t6_joint" type="revolute">
          <pose>0.23259264729715001 -0.279859905526749 0.097524622545964598 0 0 -0.00013316066694242103</pose>
          <parent>chassis_link</parent>
          <child>t6_link</child>
          <axis>
            <xyz>1 0 0</xyz>
          </axis>
      </joint>

      <plugin filename="gz-sim-thruster-system" name="gz::sim::systems::Thruster">
        <namespace>ags</namespace>
        <joint_name>t6_joint</joint_name>
        <thrust_coefficient>0.02</thrust_coefficient>
        <fluid_density>1000.0</fluid_density>
        <propeller_diameter>0.1</propeller_diameter>
        <velocity_control>true</velocity_control>
        <use_angvel_cmd>false</use_angvel_cmd>
      </plugin>
    

    
      <!--_______________________thruster 7_______________________-->
      <link name="t7_link">
        <inertial>
          <pose>-4.1153E-07 -0.00055898 -0.0039322 0 0 0</pose>
          <mass>0.226</mass>
          <inertia>
            <ixx>0.00013148</ixx>
            <ixy>-1.6857E-09</ixy>
            <ixz>-1.9632E-09</ixz>
            <iyy>0.00012745</iyy>
            <iyz>-1.4772E-07</iyz>
            <izz>0.00018193</izz>
          </inertia>
        </inertial>

        <visual name="t7v">
          <pose>0 0 0 0 0 0</pose>
          <geometry>
            <mesh>
              <scale>1 1 1</scale>
              <uri>model://meshes/t7_link.STL</uri>
            </mesh>
          </geometry>
          <material>
            <script>
              <uri>file://media/materials/scripts/gazebo.material</uri>
                <name>Gazebo/Blue</name>
            </script>
          </material>
        </visual>

        <collision name="t7c">
          <pose>0 0 0 0 0 0</pose>
          <geometry>
            <mesh>
              <uri>model://meshes/t7_link.STL</uri>
            </mesh>
          </geometry>
        </collision>

      <pose>-0.0374073503090634 -0.279823952146783 0.0975246225459653 0.0 0.0 -0.000133160666942421</pose>
      </link>
      
      <joint name="t7_joint" type="revolute">
          <pose>-0.037407350309063399 -0.27982395214678302 0.097524622545965306 0 0 -0.00013316066694242103</pose>
          <parent>chassis_link</parent>
          <child>t7_link</child>
          <axis>
            <xyz>1 0 0</xyz>
          </axis>
      </joint>

      <plugin filename="gz-sim-thruster-system" name="gz::sim::systems::Thruster">
        <namespace>ags</namespace>
        <joint_name>t7_joint</joint_name>
        <thrust_coefficient>0.02</thrust_coefficient>
        <fluid_density>1000.0</fluid_density>
        <propeller_diameter>0.1</propeller_diameter>
        <velocity_control>true</velocity_control>
        <use_angvel_cmd>false</use_angvel_cmd>
      </plugin>
   

    
      <!--_______________________thruster 8_______________________-->
      <link name="t8_link">
        <inertial>
          <pose>-4.1153E-07 -0.00055898 -0.0039322 0 0 0</pose>
          <mass>0.226</mass>
          <inertia>
            <ixx>0.00013148</ixx>
            <ixy>-1.6857E-09</ixy>
            <ixz>-1.9632E-09</ixz>
            <iyy>0.00012745</iyy>
            <iyz>-1.4772E-07</iyz>
            <izz>0.00018193</izz>
          </inertia>
        </inertial>

        <visual name="t8v">
          <pose>0 0 0 0 0 0</pose>
          <geometry>
            <mesh>
              <scale>1 1 1</scale>
              <uri>model://meshes/t8_link.STL</uri>
            </mesh>
          </geometry>
          <material>
            <script>
              <uri>file://media/materials/scripts/gazebo.material</uri>
                <name>Gazebo/Blue</name>
            </script>
          </material>
        </visual>

        <collision name="t8c">
          <pose>0 0 0 0 0 0</pose>
          <geometry>
            <mesh>
              <uri>model://meshes/t8_link.STL</uri>
            </mesh>
          </geometry>
        </collision>

      <pose>-0.0373634072891034 0.0501760449274767 0.0975246225459679 0.0 0.0 3.14145949292285</pose>
      </link>
      
      <joint name="t8_joint" type="revolute">
          <pose>-0.037363407289103402 0.050176044927476703 0.097524622545967901 0 0 3.1414594929228499</pose>
          <parent>chassis_link</parent>
          <child>t8_link</child>
          <axis>
            <xyz>1 0 0</xyz>
          </axis>
      </joint>

      <plugin filename="gz-sim-thruster-system" name="gz::sim::systems::Thruster">
        <namespace>ags</namespace>
        <joint_name>t8_joint</joint_name>
        <thrust_coefficient>0.02</thrust_coefficient>
        <fluid_density>1000.0</fluid_density>
        <propeller_diameter>0.1</propeller_diameter>
        <velocity_control>true</velocity_control>
        <use_angvel_cmd>false</use_angvel_cmd>
      </plugin>


  </model>
</sdf>